Workbook

Sheet GroupMark
C1: Nhom 1 | D1: Nhom 2 | E1: Nhom 3 | F1: Nhom 4 | G1: Nhom 5 | H1: Nhom 6 | I1: Nhom 7 | J1: Nhom 8 | K1: Nhom 9 | L1: Nhom 10 | M1: Nhom 11 | N1: Nhom 12 | O1: Nhom 13 | P1: Nhom 15
A2: Task 1: Software Architecture Design: 55% | C2: =C3*$B$3+C4*$B$4+C5+C9*$B$9+C10+C16*$B$16 -> 0 | D2: =D3*$B$3+D4*$B$4+D5+D9*$B$9+D10+D16*$B$16 -> 0 | E2: =E3*$B$3+E4*$B$4+E5+E9*$B$9+E10+E16*$B$16 -> 0 | F2: =F3*$B$3+F4*$B$4+F5+F9*$B$9+F10+F16*$B$16 -> 0 | G2: =G3*$B$3+G4*$B$4+G5+G9*$B$9+G10+G16*$B$16 -> 0 | H2: =H3*$B$3+H4*$B$4+H5+H9*$B$9+H10+H16*$B$16 -> 0 | I2: =I3*$B$3+I4*$B$4+I5+I9*$B$9+I10+I16*$B$16 -> 0 | J2: =J3*$B$3+J4*$B$4+J5+J9*$B$9+J10+J16*$B$16 -> 0 | ... O2: =O3*$B$3+O4*$B$4+O5+O9*$B$9+O10+O16*$B$16 -> 0
A3: 1. Thoroughly describe the context of ITS: 5% | B3: 0.05
A4: 2. Compare and choose suitable architecture styles: 3% | B4: 0.03
A5: 3. Create the software architecture for the ITS: 20% | C5: =C6*$B$6+C7*$B$7+C8*$B$8 -> 0 | D5: =D6*$B$6+D7*$B$7+D8*$B$8 -> 0 | E5: =E6*$B$6+E7*$B$7+E8*$B$8 -> 0 | F5: =F6*$B$6+F7*$B$7+F8*$B$8 -> 0 | G5: =G6*$B$6+G7*$B$7+G8*$B$8 -> 0 | H5: =H6*$B$6+H7*$B$7+H8*$B$8 -> 0 | I5: =I6*$B$6+I7*$B$7+I8*$B$8 -> 0 | J5: =J6*$B$6+J7*$B$7+J8*$B$8 -> 0 | ... O5: =O6*$B$6+O7*$B$7+O8*$B$8 -> 0
A6: 3.1. Module view: 12% | B6: 0.12
A7: 3.2. Component-and-Connector view: 5% | B7: 0.05
A8: 3.3. Allocation view: 3% | B8: 0.03
A9: 4. Create a UML Class Diagram: 7% | B9: 0.07
A10: 5. Apply SOLID Principles to the design: 15% | C10: =C11*$B$11+C12*$B$12+C13*$B$13+C14*$B$14+C15*$B$15 -> 0 | D10: =D11*$B$11+D12*$B$12+D13*$B$13+D14*$B$14+D15*$B$15 -> 0 | E10: =E11*$B$11+E12*$B$12+E13*$B$13+E14*$B$14+E15*$B$15 -> 0 | F10: =F11*$B$11+F12*$B$12+F13*$B$13+F14*$B$14+F15*$B$15 -> 0 | G10: =G11*$B$11+G12*$B$12+G13*$B$13+G14*$B$14+G15*$B$15 -> 0 | H10: =H11*$B$11+H12*$B$12+H13*$B$13+H14*$B$14+H15*$B$15 -> 0 | I10: =I11*$B$11+I12*$B$12+I13*$B$13+I14*$B$14+I15*$B$15 -> 0 | J10: =J11*$B$11+J12*$B$12+J13*$B$13+J14*$B$14+J15*$B$15 -> 0 | ... O10: =O11*$B$11+O12*$B$12+O13*$B$13+O14*$B$14+O15*$B$15 -> 0
A11: 5.1. Single Responsibility: 3% | B11: 0.03
A12: 5.2. Open/Closed: 3% | B12: 0.03
A13: 5.3. Liskov Substitution: 3% | B13: 0.03
A14: 5.4. Interface Segregation: 3% | B14: 0.03
A15: 5.5. Dependency Inversion: 3% | B15: 0.03
A16: 6. Future Extensibility: 5% | B16: 0.05
A17: Task 2: Code Implementation: 30% | C17: =C18+C21 -> 0 | D17: =D18+D21 -> 0 | E17: =E18+E21 -> 0 | F17: =F18+F21 -> 0 | G17: =G18+G21 -> 0 | H17: =H18+H21 -> 0 | I17: =I18+I21 -> 0 | J17: =J18+J21 -> 0 | ... O17: =O18+O21 -> 0
A18: 1. Implement Core Functionalities: 15% | C18: =C19*$B$19+C20*$B$20 -> 0 | D18: =D19*$B$19+D20*$B$20 -> 0 | E18: =E19*$B$19+E20*$B$20 -> 0 | F18: =F19*$B$19+F20*$B$20 -> 0 | G18: =G19*$B$19+G20*$B$20 -> 0 | H18: =H19*$B$19+H20*$B$20 -> 0 | I18: =I19*$B$19+I20*$B$20 -> 0 | J18: =J19*$B$19+J20*$B$20 -> 0 | ... O18: =O19*$B$19+O20*$B$20 -> 0
A19: 1.1. The chosen functionalities run correctly (in total): 15% | B19: 0.15
A20: 1.2. Implement more than 1 module: +10% (bonus) | B20: 0.1
A21: 2. Apply SOLID Principles in Code: 15% | C21: =C22*$B$22+C23*$B$23+C24*$B$24+C25*$B$25+C26*$B$26 -> 0 | D21: =D22*$B$22+D23*$B$23+D24*$B$24+D25*$B$25+D26*$B$26 -> 0 | E21: =E22*$B$22+E23*$B$23+E24*$B$24+E25*$B$25+E26*$B$26 -> 0 | F21: =F22*$B$22+F23*$B$23+F24*$B$24+F25*$B$25+F26*$B$26 -> 0 | G21: =G22*$B$22+G23*$B$23+G24*$B$24+G25*$B$25+G26*$B$26 -> 0 | H21: =H22*$B$22+H23*$B$23+H24*$B$24+H25*$B$25+H26*$B$26 -> 0 | I21: =I22*$B$22+I23*$B$23+I24*$B$24+I25*$B$25+I26*$B$26 -> 0 | J21: =J22*$B$22+J23*$B$23+J24*$B$24+J25*$B$25+J26*$B$26 -> 0 | ... O21: =O22*$B$22+O23*$B$23+O24*$B$24+O25*$B$25+O26*$B$26 -> 0
A22: 2.1. Single Responsibility: 3% | B22: 0.03
A23: 2.2. Open/Closed: 3% | B23: 0.03
A24: 2.3. Liskov Substitution: 3% | B24: 0.03
A25: 2.4. Interface Segregation: 3% | B25: 0.03
A26: 2.5. Dependency Inversion: 3% | B26: 0.03
A27: Task 3: Documentation and Reporting: 5% | C27: =C28*$B$28+C29*$B$29 -> 0 | D27: =D28*$B$28+D29*$B$29 -> 0 | E27: =E28*$B$28+E29*$B$29 -> 0 | F27: =F28*$B$28+F29*$B$29 -> 0 | G27: =G28*$B$28+G29*$B$29 -> 0 | H27: =H28*$B$28+H29*$B$29 -> 0 | I27: =I28*$B$28+I29*$B$29 -> 0 | J27: =J28*$B$28+J29*$B$29 -> 0 | ... O27: =O28*$B$28+O29*$B$29 -> 0
A28: 1. Reflection Report: 3% | B28: 0.03
A29: 2. Division of work: 2% | B29: 0.02
A30: Presentation (demo): 10% | C30: =C31*$B$31+C32*$B$32+C33*$B$33+C34*$B$34 -> 0 | D30: =D31*$B$31+D32*$B$32+D33*$B$33+D34*$B$34 -> 0 | E30: =E31*$B$31+E32*$B$32+E33*$B$33+E34*$B$34 -> 0 | F30: =F31*$B$31+F32*$B$32+F33*$B$33+F34*$B$34 -> 0 | G30: =G31*$B$31+G32*$B$32+G33*$B$33+G34*$B$34 -> 0 | H30: =H31*$B$31+H32*$B$32+H33*$B$33+H34*$B$34 -> 0 | I30: =I31*$B$31+I32*$B$32+I33*$B$33+I34*$B$34 -> 0 | J30: =J31*$B$31+J32*$B$32+J33*$B$33+J34*$B$34 -> 0 | ... O30: =O31*$B$31+O32*$B$32+O33*$B$33+O34*$B$34 -> 0
A31: + Demo: 2% | B31: 0.02
A32: + Presentation skills: 3% | B32: 0.03
A33: + Slides: 3% | B33: 0.03
A34: + Q&A: 2% | B34: 0.02
A35: SEMIAR (+10%) BOUNUS | B35: 0.1
A36: Total (100%) | C36: =MIN(10, ROUND((C2+C17+C27+C30+10%*C35),1)) -> 0 | D36: =MIN(10, ROUND((D2+D17+D27+D30+10%*D35),1)) -> 0 | E36: =MIN(10, ROUND((E2+E17+E27+E30+10%*E35),1)) -> 0 | F36: =MIN(10, ROUND((F2+F17+F27+F30+10%*F35),1)) -> 0 | G36: =MIN(10, ROUND((G2+G17+G27+G30+10%*G35),1)) -> 0 | H36: =MIN(10, ROUND((H2+H17+H27+H30+10%*H35),1)) -> 0 | I36: =MIN(10, ROUND((I2+I17+I27+I30+10%*I35),1)) -> 0 | J36: =MIN(10, ROUND((J2+J17+J27+J30+10%*J35),1)) -> 0 | ... O36: =MIN(10, ROUND((O2+O17+O27+O30+10%*O35),1)) -> 0
A38: Note

Sheet Group_Infos
A1: MSSV | B1: Họ và tên | C1: Mail | D1: Nhóm
A2: 2312562 | B2: Lữ Quốc Pháp | C2: phap.luquoc@hcmut.edu.vn | D2: 1
A3: 2312365 | B3: Nguyễn Lê Nguyên | C3: nguyen.nguyenbkukmt@hcmut.edu.vn
A4: 2312285 | B4: Trần Trọng Nghĩa | C4: nghia.trantrong0409@hcmut.edu.vn
A5: 2312791 | B5: Lê Sĩ Nhật Quang
A6: 2312749 | B6: Nguyễn Đức Phương
A7: 2312097 | B7: Nguyễn Thiện Minh | C7: minh.nguyenrun@hcmut.edu.vn | D7: 2
A8: 2314019 | B8: Nguyễn Vạn Xuân | C8: xuan.nguyenvanxuan@hcmut.edu.vn
A9: 2311051 | B9: Nguyễn Đặng Thế Hoàng | C9: hoang.nguyen1011@hcmut.edu.vn
A10: 2313834 | B10: Nguyễn Vũ Tường | C10: tuong.nguyenvu106k23@hcmut.edu.vn
A11: 2310854 | B11: Nguyễn Trọng Hào | C11: hao.nguyenrohan695@hcmut.edu.vn
A12: 2312776 | B12: Nguyễn Tấn Phước | C12: phuoc.nguyen2005@hcmut.edu.vn | D12: 3
A13: 2313749 | B13: Nguyễn Minh Tuấn | C13: tuan.nguyencapoo@hcmut.edu.vn
A14: 2313771 | B14: Vũ Anh Tuấn | C14: tuan.vuatuan2k4@hcmut.edu.vn
A15: 2213057 | B15: Nguyễn Minh Tân | C15: tan.nguyendn14042004@hcmut.edu.vn
A16: 2210590 | B16: Nguyễn Văn Dũng | C16: dung.nguyenvan3864@hcmut.edu.vn
A17: 2212757 | B17: Trần Minh Quang | C17: quang.tranminh@hcmut.edu.vn
A18: 2210576 | B18: Lê Trần Anh Dũng | C18: dung.letrananh@hcmut.edu.vn | D18: 4
A19: 2311514 | B19: Nguyễn Gia Khánh | C19: khanh.nguyen0403@hcmut.edu.vn
A20: 2313962 | B20: Nguyễn Tăng Vũ | C20: vu.nguyenntv412305@hcmut.edu.vn
A21: 2210510 | B21: Nguyễn Đức Duy | C21: duy.nguyen1010fight@hcmut.edu.vn
A22: 2310393 | B22: Nguyễn Hữu Thiên Cường | C22: cuong.nguyenhuuthien@hcmut.edu.vn
A23: 2313966 | B23: Phạm Xuân Vũ | C23: vu.phamxuan2806@hcmut.edu.vn
A24: 2311849 | B24: Lê Bảo Linh | C24: linh.lee@hcmut.edu.vn | D24: 5
A25: 2210400 | B25: Phạm Đình Chương | C25: chuong.phamwarclork@hcmut.edu.vn
A26: 2213059 | B26: Nguyễn Nhật Tân | C26: tan.nguyennhat2k4@hcmut.edu.vn
A27: 1952924 | B27: Trần Phú | C27: phu.tranfirewall00@hcmut.edu.vn
A28: 2310735 | B28: Trần Minh Đăng | C28: dang.tran2310735da@hcmut.edu.vn
A29: 2313907 | B29: Hà Đình Vinh | C29: vinh.ha230905@hcmut.edu.vn
A30: 2310707 | B30: Trần Tiến Đạt | C30: dat.tran3012@gmail.com | D30: 6
A31: 2310559 | B31: Nguyễn Phạm Mạnh Dũng | C31: dung.nguyen29105@hcmut.edu.vn
A32: 2310730 | B32: Nguyễn Ngọc Hải Đăng | C32: dang.nguyen25102005@hcmut.edu.vn
A33: 2310856 | B33: Trần Anh Hào | C33: hao.trananhhao71@hcmut.edu.vn
A34: 2310979 | B34: Trần Phạm Minh Hiếu | C34: hieu.tran3125@hcmut.edu.vn
A35: 2310615 | B35: Đặng Thành Duy Đan | C35: dan.dang2005@hcmut.edu.vn
A36: 2311896 | B36: Đỗ Quang Long | C36: long.doquang1896@hcmut.edu.vn | D36: 7
A37: 2311982 | B37: Lê Hoàng Luân | C37: luan.le2311982@hcmut.edu.vn
A38: 2310990 | B38: Lê Thúy Hiền | C38: hien.lethuy@hcmut.edu.vn
A39: 2213698 | B39: Nguyễn Hải Trung | C39: trung.nguyen2004@hcmut.edu.vn
A40: 2211384 | B40: Tô Thế Hưng | C40: hung.totothehung@hcmut.edu.vn
...
